Workbook

Sheet Posts
A1: Post ID | B1: Platform | C1: Date | D1: Content Type | E1: Post Text | F1: Likes | G1: Shares | H1: Comments | I1: Impressions | J1: Engagement Rate | K1: Reach | L1: Clicks | M1: Hashtags Used_1 | N1: Hashtags Used_2 | O1: Campaign_Name | P1: Total Enagagement
A2: SP001 | B2: Instagram | C2: 45781 | D2: Text | E2: Discover fresh beats on Spotify! | F2: 2414 | G2: 245 | H2: 137 | I2: 21181 | J2: =(Posts[[#This Row],[Likes]]+Posts[[#This Row],[Shares]]+Posts[[#This Row],[Comments]])/Posts[[#This Row],[Impressions]] -> 0.1320051 | K2: 45292 | L2: 133 | M2: #SoundtrackOfLife | N2: #NowPlaying | O2: ChillVibes | P2: =SUM(Posts[[#This Row],[Likes]:[Comments]]) -> 2796
A3: SP002 | B3: Instagram | C3: 45689 | D3: Text | E3: Explore the latest podcasts now. | F3: 1934 | G3: 210 | H3: 393 | I3: 29129 | J3: =(Posts[[#This Row],[Likes]]+Posts[[#This Row],[Shares]]+Posts[[#This Row],[Comments]])/Posts[[#This Row],[Impressions]] -> 0.087095335 | K3: 73287 | L3: 273 | M3: #DiscoverWeekly | O3: IndieWave | P3: =SUM(Posts[[#This Row],[Likes]:[Comments]]) -> 2537
A4: SP003 | B4: Twitter | C4: 45629 | D4: Story | E4: New music just dropped. Hit play! | F4: 3092 | G4: 177 | H4: 81 | I4: 47533 | J4: =(Posts[[#This Row],[Likes]]+Posts[[#This Row],[Shares]]+Posts[[#This Row],[Comments]])/Posts[[#This Row],[Impressions]] -> 0.070477353 | K4: 29220 | L4: 121 | M4: #MusicForEveryone | N4: #NowPlaying | O4: ChillVibes | P4: =SUM(Posts[[#This Row],[Likes]:[Comments]]) -> 3350
A5: SP004 | B5: Instagram | C5: 45629 | D5: Text | E5: Wrapped is here! Relive your top tracks ðŸŽ§ | F5: 3173 | G5: 229 | H5: 197 | I5: 29604 | J5: =(Posts[[#This Row],[Likes]]+Posts[[#This Row],[Shares]]+Posts[[#This Row],[Comments]])/Posts[[#This Row],[Impressions]] -> 0.12157141 | K5: 21809 | L5: 272 | M5: #SoundtrackOfLife | N5: #NowPlaying | O5: ChillVibes | P5: =SUM(Posts[[#This Row],[Likes]:[Comments]]) -> 3599
A6: SP005 | B6: YouTube | C6: 45388 | D6: Text | E6: Music that moves youâ€”only on Spotify. | F6: 2748 | G6: 145 | H6: 315 | I6: 24401 | J6: =(Posts[[#This Row],[Likes]]+Posts[[#This Row],[Shares]]+Posts[[#This Row],[Comments]])/Posts[[#This Row],[Impressions]] -> 0.13147002 | K6: 61182 | L6: 200 | M6: #DiscoverWeekly | N6: #SpotifyWrapped | O6: IndieWave | P6: =SUM(Posts[[#This Row],[Likes]:[Comments]]) -> 3208
A7: SP006 | B7: YouTube | C7: 45456 | D7: Text | E7: Whatâ€™s your vibe today? #SpotifyHits | F7: 3882 | G7: 239 | H7: 275 | I7: 58748 | J7: =(Posts[[#This Row],[Likes]]+Posts[[#This Row],[Shares]]+Posts[[#This Row],[Comments]])/Posts[[#This Row],[Impressions]] -> 0.074828079 | K7: 44646 | L7: 149 | M7: #DiscoverWeekly | N7: #SpotifyWrapped | O7: IndieWave | P7: =SUM(Posts[[#This Row],[Likes]:[Comments]]) -> 4396
A8: SP007 | B8: Twitter | C8: 45645 | D8: Story | E8: Get into the groove with our new drop! | F8: 4674 | G8: 409 | H8: 327 | I8: 20756 | J8: =(Posts[[#This Row],[Likes]]+Posts[[#This Row],[Shares]]+Posts[[#This Row],[Comments]])/Posts[[#This Row],[Impressions]] -> 0.26064752 | K8: 63599 | L8: 212 | M8: #SoundtrackOfLife | N8: #NowPlaying | O8: ChillVibes | P8: =SUM(Posts[[#This Row],[Likes]:[Comments]]) -> 5410
A9: SP008 | B9: Twitter | C9: 45421 | D9: Story | E9: Wrapped is here! Relive your top tracks ðŸŽ§ | F9: 1428 | G9: 347 | H9: 67 | I9: 21148 | J9: =(Posts[[#This Row],[Likes]]+Posts[[#This Row],[Shares]]+Posts[[#This Row],[Comments]])/Posts[[#This Row],[Impressions]] -> 0.087100435 | K9: 19712 | L9: 120 | M9: #DiscoverWeekly | N9: #MusicForEveryone | O9: ChillVibes | P9: =SUM(Posts[[#This Row],[Likes]:[Comments]]) -> 1842
A10: SP009 | B10: Twitter | C10: 45823 | D10: Text | E10: Top trending tracks updated daily! | F10: 4432 | G10: 223 | H10: 299 | I10: 59016 | J10: =(Posts[[#This Row],[Likes]]+Posts[[#This Row],[Shares]]+Posts[[#This Row],[Comments]])/Posts[[#This Row],[Impressions]] -> 0.083943337 | K10: 21742 | L10: 171 | M10: #NowPlaying | O10: ChillVibes | P10: =SUM(Posts[[#This Row],[Likes]:[Comments]]) -> 4954
A11: SP010 | B11: Twitter | C11: 45630 | D11: Text | E11: Wrapped is here! Relive your top tracks ðŸŽ§ | F11: 2357 | G11: 274 | H11: 172 | I11: 21566 | J11: =(Posts[[#This Row],[Likes]]+Posts[[#This Row],[Shares]]+Posts[[#This Row],[Comments]])/Posts[[#This Row],[Impressions]] -> 0.12997311 | K11: 66829 | L11: 284 | M11: #NowPlaying | O11: ChillVibes | P11: =SUM(Posts[[#This Row],[Likes]:[Comments]]) -> 2803
A12: SP011 | B12: Twitter | C12: 45357 | D12: Text | E12: Discover fresh beats on Spotify! | F12: 1971 | G12: 370 | H12: 306 | I12: 31316 | J12: =(Posts[[#This Row],[Likes]]+Posts[[#This Row],[Shares]]+Posts[[#This Row],[Comments]])/Posts[[#This Row],[Impressions]] -> 0.084525482 | K12: 27897 | L12: 88 | M12: #SoundtrackOfLife | O12: IndieWave | P12: =SUM(Posts[[#This Row],[Likes]:[Comments]]) -> 2647
A13: SP012 | B13: Instagram | C13: 45426 | D13: Text | E13: Discover fresh beats on Spotify! | F13: 1485 | G13: 353 | H13: 244 | I13: 38419 | J13: =(Posts[[#This Row],[Likes]]+Posts[[#This Row],[Shares]]+Posts[[#This Row],[Comments]])/Posts[[#This Row],[Impressions]] -> 0.054191936 | K13: 38556 | L13: 86 | M13: #SoundtrackOfLife | N13: #NowPlaying | O13: ChillVibes | P13: =SUM(Posts[[#This Row],[Likes]:[Comments]]) -> 2082
A14: SP013 | B14: Twitter | C14: 45826 | D14: Story | E14: Discover fresh beats on Spotify! | F14: 3956 | G14: 319 | H14: 61 | I14: 58162 | J14: =(Posts[[#This Row],[Likes]]+Posts[[#This Row],[Shares]]+Posts[[#This Row],[Comments]])/Posts[[#This Row],[Impressions]] -> 0.074550394 | K14: 28720 | L14: 213 | M14: #MusicForEveryone | N14: #NowPlaying | O14: ChillVibes | P14: =SUM(Posts[[#This Row],[Likes]:[Comments]]) -> 4336
A15: SP014 | B15: Twitter | C15: 45573 | D15: Text | E15: From pop to podcasts, itâ€™s all here. | F15: 2460 | G15: 409 | H15: 253 | I15: 36702 | J15: =(Posts[[#This Row],[Likes]]+Posts[[#This Row],[Shares]]+Posts[[#This Row],[Comments]])/Posts[[#This Row],[Impressions]] -> 0.085063484 | K15: 46122 | L15: 264 | M15: #NowPlaying | O15: ChillVibes | P15: =SUM(Posts[[#This Row],[Likes]:[Comments]]) -> 3122
A16: SP015 | B16: Twitter | C16: 45418 | D16: Text | E16: Your weekend playlist is waiting. | F16: 3476 | G16: 355 | H16: 396 | I16: 37492 | J16: =(Posts[[#This Row],[Likes]]+Posts[[#This Row],[Shares]]+Posts[[#This Row],[Comments]])/Posts[[#This Row],[Impressions]] -> 0.11274405 | K16: 27285 | L16: 179 | M16: #NowPlaying | O16: ChillVibes | P16: =SUM(Posts[[#This Row],[Likes]:[Comments]]) -> 4227
A17: SP016 | B17: Twitter | C17: 45655 | D17: Story | E17: New music just dropped. Hit play! | F17: 4049 | G17: 377 | H17: 94 | I17: 48182 | J17: =(Posts[[#This Row],[Likes]]+Posts[[#This Row],[Shares]]+Posts[[#This Row],[Comments]])/Posts[[#This Row],[Impressions]] -> 0.093810967 | K17: 42875 | L17: 172 | M17: #MusicForEveryone | N17: #NowPlaying | O17: ChillVibes | P17: =SUM(Posts[[#This Row],[Likes]:[Comments]]) -> 4520
A18: SP017 | B18: Twitter | C18: 45453 | D18: Text | E18: Whatâ€™s your vibe today? #SpotifyHits | F18: 1514 | G18: 164 | H18: 275 | I18: 41364 | J18: =(Posts[[#This Row],[Likes]]+Posts[[#This Row],[Shares]]+Posts[[#This Row],[Comments]])/Posts[[#This Row],[Impressions]] -> 0.04721497 | K18: 44389 | L18: 83 | M18: #NowPlaying | O18: ChillVibes | P18: =SUM(Posts[[#This Row],[Likes]:[Comments]]) -> 1953
A19: SP018 | B19: Instagram | C19: 45325 | D19: Story | E19: Music that moves youâ€”only on Spotify. | F19: 4281 | G19: 101 | H19: 163 | I19: 32278 | J19: =(Posts[[#This Row],[Likes]]+Posts[[#This Row],[Shares]]+Posts[[#This Row],[Comments]])/Posts[[#This Row],[Impressions]] -> 0.14080798 | K19: 53382 | L19: 235 | M19: #NowPlaying | O19: Wrapped2024 | P19: =SUM(Posts[[#This Row],[Likes]:[Comments]]) -> 4545
A20: SP019 | B20: YouTube | C20: 45458 | D20: Reel | E20: Get into the groove with our new drop! | F20: 1751 | G20: 143 | H20: 151 | I20: 31826 | J20: =(Posts[[#This Row],[Likes]]+Posts[[#This Row],[Shares]]+Posts[[#This Row],[Comments]])/Posts[[#This Row],[Impressions]] -> 0.06425564 | K20: 47729 | L20: 95 | M20: #DiscoverWeekly | N20: #SoundtrackOfLife | O20: SummerBeats | P20: =SUM(Posts[[#This Row],[Likes]:[Comments]]) -> 2045
A21: SP020 | B21: Instagram | C21: 45478 | D21: Text | E21: Your weekend playlist is waiting. | F21: 3753 | G21: 411 | H21: 308 | I21: 29138 | J21: =(Posts[[#This Row],[Likes]]+Posts[[#This Row],[Shares]]+Posts[[#This Row],[Comments]])/Posts[[#This Row],[Impressions]] -> 0.15347656 | K21: 27678 | L21: 90 | M21: #DiscoverWeekly | O21: IndieWave | P21: =SUM(Posts[[#This Row],[Likes]:[Comments]]) -> 4472
A22: SP021 | B22: Instagram | C22: 45603 | D22: Story | E22: Wrapped is here! Relive your top tracks ðŸŽ§ | F22: 1678 | G22: 423 | H22: 323 | I22: 55668 | J22: =(Posts[[#This Row],[Likes]]+Posts[[#This Row],[Shares]]+Posts[[#This Row],[Comments]])/Posts[[#This Row],[Impressions]] -> 0.043543867 | K22: 37945 | L22: 230 | M22: #NowPlaying | O22: Wrapped2024 | P22: =SUM(Posts[[#This Row],[Likes]:[Comments]]) -> 2424
A23: SP022 | B23: Instagram | C23: 45823 | D23: Text | E23: Whatâ€™s your vibe today? #SpotifyHits | F23: 4896 | G23: 466 | H23: 233 | I23: 28621 | J23: =(Posts[[#This Row],[Likes]]+Posts[[#This Row],[Shares]]+Posts[[#This Row],[Comments]])/Posts[[#This Row],[Impressions]] -> 0.19548583 | K23: 34270 | L23: 84 | M23: #SoundtrackOfLife | N23: #NowPlaying | O23: ChillVibes | P23: =SUM(Posts[[#This Row],[Likes]:[Comments]]) -> 5595
A24: SP023 | B24: YouTube | C24: 45452 | D24: Reel | E24: From pop to podcasts, itâ€™s all here. | F24: 2786 | G24: 368 | H24: 208 | I24: 42000 | J24: =(Posts[[#This Row],[Likes]]+Posts[[#This Row],[Shares]]+Posts[[#This Row],[Comments]])/Posts[[#This Row],[Impressions]] -> 0.080047619 | K24: 39967 | L24: 103 | M24: #DiscoverWeekly | N24: #SoundtrackOfLife | O24: SummerBeats | P24: =SUM(Posts[[#This Row],[Likes]:[Comments]]) -> 3362
A25: SP024 | B25: Twitter | C25: 45583 | D25: Text | E25: New music just dropped. Hit play! | F25: 2607 | G25: 379 | H25: 180 | I25: 28712 | J25: =(Posts[[#This Row],[Likes]]+Posts[[#This Row],[Shares]]+Posts[[#This Row],[Comments]])/Posts[[#This Row],[Impressions]] -> 0.11026748 | K25: 61620 | L25: 174 | M25: #SoundtrackOfLife | O25: IndieWave | P25: =SUM(Posts[[#This Row],[Likes]:[Comments]]) -> 3166
A26: SP025 | B26: YouTube | C26: 45575 | D26: Reel | E26: From pop to podcasts, itâ€™s all here. | F26: 4013 | G26: 320 | H26: 92 | I26: 54605 | J26: =(Posts[[#This Row],[Likes]]+Posts[[#This Row],[Shares]]+Posts[[#This Row],[Comments]])/Posts[[#This Row],[Impressions]] -> 0.081036535 | K26: 60169 | L26: 232 | M26: #DiscoverWeekly | N26: #SoundtrackOfLife | O26: SummerBeats | P26: =SUM(Posts[[#This Row],[Likes]:[Comments]]) -> 4425
A27: SP026 | B27: Twitter | C27: 45791 | D27: Story | E27: From pop to podcasts, itâ€™s all here. | F27: 2707 | G27: 103 | H27: 51 | I27: 55302 | J27: =(Posts[[#This Row],[Likes]]+Posts[[#This Row],[Shares]]+Posts[[#This Row],[Comments]])/Posts[[#This Row],[Impressions]] -> 0.051734114 | K27: 18801 | L27: 147 | M27: #DiscoverWeekly | N27: #MusicForEveryone | O27: ChillVibes | P27: =SUM(Posts[[#This Row],[Likes]:[Comments]]) -> 2861
A28: SP027 | B28: Instagram | C28: 45625 | D28: Text | E28: Whatâ€™s your vibe today? #SpotifyHits | F28: 2824 | G28: 425 | H28: 274 | I28: 31004 | J28: =(Posts[[#This Row],[Likes]]+Posts[[#This Row],[Shares]]+Posts[[#This Row],[Comments]])/Posts[[#This Row],[Impressions]] -> 0.1136305 | K28: 53488 | L28: 268 | M28: #SoundtrackOfLife | N28: #NowPlaying | O28: ChillVibes | P28: =SUM(Posts[[#This Row],[Likes]:[Comments]]) -> 3523
A29: SP028 | B29: YouTube | C29: 45356 | D29: Reel | E29: Explore the latest podcasts now. | F29: 3558 | G29: 314 | H29: 199 | I29: 49612 | J29: =(Posts[[#This Row],[Likes]]+Posts[[#This Row],[Shares]]+Posts[[#This Row],[Comments]])/Posts[[#This Row],[Impressions]] -> 0.08205676 | K29: 53929 | L29: 206 | M29: #DiscoverWeekly | N29: #SoundtrackOfLife | O29: SummerBeats | P29: =SUM(Posts[[#This Row],[Likes]:[Comments]]) -> 4071
A30: SP029 | B30: Twitter | C30: 45734 | D30: Story | E30: Explore the latest podcasts now. | F30: 3418 | G30: 188 | H30: 387 | I30: 57431 | J30: =(Posts[[#This Row],[Likes]]+Posts[[#This Row],[Shares]]+Posts[[#This Row],[Comments]])/Posts[[#This Row],[Impressions]] -> 0.069526911 | K30: 36933 | L30: 202 | M30: #MusicForEveryone | N30: #NowPlaying | O30: ChillVibes | P30: =SUM(Posts[[#This Row],[Likes]:[Comments]]) -> 3993
A31: SP030 | B31: Twitter | C31: 45773 | D31: Text | E31: Discover fresh beats on Spotify! | F31: 2411 | G31: 194 | H31: 168 | I31: 26665 | J31: =(Posts[[#This Row],[Likes]]+Posts[[#This Row],[Shares]]+Posts[[#This Row],[Comments]])/Posts[[#This Row],[Impressions]] -> 0.103994 | K31: 71699 | L31: 197 | M31: #NowPlaying | O31: ChillVibes | P31: =SUM(Posts[[#This Row],[Likes]:[Comments]]) -> 2773
A32: SP031 | B32: Instagram | C32: 45658 | D32: Text | E32: New music just dropped. Hit play! | F32: 4036 | G32: 112 | H32: 382 | I32: 56284 | J32: =(Posts[[#This Row],[Likes]]+Posts[[#This Row],[Shares]]+Posts[[#This Row],[Comments]])/Posts[[#This Row],[Impressions]] -> 0.080484685 | K32: 29440 | L32: 279 | M32: #SoundtrackOfLife | N32: #NowPlaying | O32: ChillVibes | P32: =SUM(Posts[[#This Row],[Likes]:[Comments]]) -> 4530
A33: SP032 | B33: Twitter | C33: 45419 | D33: Story | E33: Explore the latest podcasts now. | F33: 2776 | G33: 307 | H33: 178 | I33: 43365 | J33: =(Posts[[#This Row],[Likes]]+Posts[[#This Row],[Shares]]+Posts[[#This Row],[Comments]])/Posts[[#This Row],[Impressions]] -> 0.075198893 | K33: 48408 | L33: 138 | M33: #SoundtrackOfLife | N33: #NowPlaying | O33: ChillVibes | P33: =SUM(Posts[[#This Row],[Likes]:[Comments]]) -> 3261
A34: SP033 | B34: Twitter | C34: 45574 | D34: Story | E34: Discover fresh beats on Spotify! | F34: 4929 | G34: 182 | H34: 95 | I34: 32181 | J34: =(Posts[[#This Row],[Likes]]+Posts[[#This Row],[Shares]]+Posts[[#This Row],[Comments]])/Posts[[#This Row],[Impressions]] -> 0.16177247 | K34: 31084 | L34: 289 | M34: #DiscoverWeekly | N34: #MusicForEveryone | O34: ChillVibes | P34: =SUM(Posts[[#This Row],[Likes]:[Comments]]) -> 5206
A35: SP034 | B35: Instagram | C35: 45666 | D35: Text | E35: New music just dropped. Hit play! | F35: 1015 | G35: 366 | H35: 308 | I35: 38127 | J35: =(Posts[[#This Row],[Likes]]+Posts[[#This Row],[Shares]]+Posts[[#This Row],[Comments]])/Posts[[#This Row],[Impressions]] -> 0.044299315 | K35: 63790 | L35: 287 | M35: #SoundtrackOfLife | N35: #NowPlaying | O35: ChillVibes | P35: =SUM(Posts[[#This Row],[Likes]:[Comments]]) -> 1689
A36: SP035 | B36: Twitter | C36: 45785 | D36: Story | E36: Your weekend playlist is waiting. | F36: 3316 | G36: 332 | H36: 268 | I36: 40095 | J36: =(Posts[[#This Row],[Likes]]+Posts[[#This Row],[Shares]]+Posts[[#This Row],[Comments]])/Posts[[#This Row],[Impressions]] -> 0.097668038 | K36: 36913 | L36: 265 | M36: #MusicForEveryone | N36: #NowPlaying | O36: ChillVibes | P36: =SUM(Posts[[#This Row],[Likes]:[Comments]]) -> 3916
A37: SP036 | B37: Instagram | C37: 45416 | D37: Text | E37: Wrapped is here! Relive your top tracks ðŸŽ§ | F37: 2274 | G37: 243 | H37: 222 | I37: 43066 | J37: =(Posts[[#This Row],[Likes]]+Posts[[#This Row],[Shares]]+Posts[[#This Row],[Comments]])/Posts[[#This Row],[Impressions]] -> 0.063600056 | K37: 59174 | L37: 80 | M37: #DiscoverWeekly | O37: IndieWave | P37: =SUM(Posts[[#This Row],[Likes]:[Comments]]) -> 2739
A38: SP037 | B38: Twitter | C38: 45804 | D38: Story | E38: Explore the latest podcasts now. | F38: 4095 | G38: 385 | H38: 400 | I38: 45300 | J38: =(Posts[[#This Row],[Likes]]+Posts[[#This Row],[Shares]]+Posts[[#This Row],[Comments]])/Posts[[#This Row],[Impressions]] -> 0.10772627 | K38: 31795 | L38: 80 | M38: #MusicForEveryone | N38: #NowPlaying | O38: ChillVibes | P38: =SUM(Posts[[#This Row],[Likes]:[Comments]]) -> 4880
A39: SP038 | B39: Instagram | C39: 45545 | D39: Story | E39: New music just dropped. Hit play! | F39: 1230 | G39: 309 | H39: 207 | I39: 44629 | J39: =(Posts[[#This Row],[Likes]]+Posts[[#This Row],[Shares]]+Posts[[#This Row],[Comments]])/Posts[[#This Row],[Impressions]] -> 0.039122544 | K39: 40699 | L39: 195 | M39: #NowPlaying | O39: Wrapped2024 | P39: =SUM(Posts[[#This Row],[Likes]:[Comments]]) -> 1746
A40: SP039 | B40: Instagram | C40: 45621 | D40: Text | E40: From pop to podcasts, itâ€™s all here. | F40: 1341 | G40: 472 | H40: 238 | I40: 51386 | J40: =(Posts[[#This Row],[Likes]]+Posts[[#This Row],[Shares]]+Posts[[#This Row],[Comments]])/Posts[[#This Row],[Impressions]] -> 0.039913595 | K40: 51706 | L40: 133 | M40: #DiscoverWeekly | O40: IndieWave | P40: =SUM(Posts[[#This Row],[Likes]:[Comments]]) -> 2051
...

Sheet Engagement Summary
A1: Week_Start_Date | B1: Platform | C1: New_Followers | D1: Unfollows | E1: Total_Followers | F1: Net Followers | G1: growth Rate | H1: Engagement_Rate | I1: Ad_Spend
A2: 45446 | B2: Instagram | C2: 1402 | D2: 68 | E2: 124562 | F2: =Engagement_Summary[[#This Row],[New_Followers]]-Engagement_Summary[[#This Row],[Unfollows]] -> 1334 | G2: =(Engagement_Summary[[#This Row],[New_Followers]]-Engagement_Summary[[#This Row],[Unfollows]])/Engagement_Summary[[#This Row],[Total_Followers]] -> 0.010709526 | H2: 9.92 | I2: 23125
A3: 45446 | B3: Twitter | C3: 995 | D3: 86 | E3: 227958 | F3: =Engagement_Summary[[#This Row],[New_Followers]]-Engagement_Summary[[#This Row],[Unfollows]] -> 909 | G3: =(Engagement_Summary[[#This Row],[New_Followers]]-Engagement_Summary[[#This Row],[Unfollows]])/Engagement_Summary[[#This Row],[Total_Followers]] -> 0.0039875767 | H3: 8.05 | I3: 22788
A4: 45446 | B4: YouTube | C4: 1472 | D4: 296 | E4: 370242 | F4: =Engagement_Summary[[#This Row],[New_Followers]]-Engagement_Summary[[#This Row],[Unfollows]] -> 1176 | G4: =(Engagement_Summary[[#This Row],[New_Followers]]-Engagement_Summary[[#This Row],[Unfollows]])/Engagement_Summary[[#This Row],[Total_Followers]] -> 0.0031763009 | H4: 7.72 | I4: 7810
A5: 45453 | B5: Instagram | C5: 1018 | D5: 90 | E5: 92474 | F5: =Engagement_Summary[[#This Row],[New_Followers]]-Engagement_Summary[[#This Row],[Unfollows]] -> 928 | G5: =(Engagement_Summary[[#This Row],[New_Followers]]-Engagement_Summary[[#This Row],[Unfollows]])/Engagement_Summary[[#This Row],[Total_Followers]] -> 0.010035253 | H5: 9.4 | I5: 11966
A6: 45453 | B6: Twitter | C6: 1461 | D6: 64 | E6: 328902 | F6: =Engagement_Summary[[#This Row],[New_Followers]]-Engagement_Summary[[#This Row],[Unfollows]] -> 1397 | G6: =(Engagement_Summary[[#This Row],[New_Followers]]-Engagement_Summary[[#This Row],[Unfollows]])/Engagement_Summary[[#This Row],[Total_Followers]] -> 0.0042474658 | H6: 9.02 | I6: 26298
A7: 45453 | B7: YouTube | C7: 545 | D7: 93 | E7: 391621 | F7: =Engagement_Summary[[#This Row],[New_Followers]]-Engagement_Summary[[#This Row],[Unfollows]] -> 452 | G7: =(Engagement_Summary[[#This Row],[New_Followers]]-Engagement_Summary[[#This Row],[Unfollows]])/Engagement_Summary[[#This Row],[Total_Followers]] -> 0.0011541771 | H7: 9.96 | I7: 22029
A8: 45460 | B8: Instagram | C8: 881 | D8: 291 | E8: 95885 | F8: =Engagement_Summary[[#This Row],[New_Followers]]-Engagement_Summary[[#This Row],[Unfollows]] -> 590 | G8: =(Engagement_Summary[[#This Row],[New_Followers]]-Engagement_Summary[[#This Row],[Unfollows]])/Engagement_Summary[[#This Row],[Total_Followers]] -> 0.0061532044 | H8: 5.29 | I8: 12391
A9: 45460 | B9: Twitter | C9: 1414 | D9: 131 | E9: 245947 | F9: =Engagement_Summary[[#This Row],[New_Followers]]-Engagement_Summary[[#This Row],[Unfollows]] -> 1283 | G9: =(Engagement_Summary[[#This Row],[New_Followers]]-Engagement_Summary[[#This Row],[Unfollows]])/Engagement_Summary[[#This Row],[Total_Followers]] -> 0.005216571 | H9: 8.3 | I9: 14477
A10: 45460 | B10: YouTube | C10: 1472 | D10: 170 | E10: 250428 | F10: =Engagement_Summary[[#This Row],[New_Followers]]-Engagement_Summary[[#This Row],[Unfollows]] -> 1302 | G10: =(Engagement_Summary[[#This Row],[New_Followers]]-Engagement_Summary[[#This Row],[Unfollows]])/Engagement_Summary[[#This Row],[Total_Followers]] -> 0.0051990991 | H10: 4.66 | I10: 25040
A11: 45467 | B11: Instagram | C11: 809 | D11: 197 | E11: 87186 | F11: =Engagement_Summary[[#This Row],[New_Followers]]-Engagement_Summary[[#This Row],[Unfollows]] -> 612 | G11: =(Engagement_Summary[[#This Row],[New_Followers]]-Engagement_Summary[[#This Row],[Unfollows]])/Engagement_Summary[[#This Row],[Total_Followers]] -> 0.0070194756 | H11: 9.48 | I11: 22619
A12: 45467 | B12: Twitter | C12: 1371 | D12: 250 | E12: 128620 | F12: =Engagement_Summary[[#This Row],[New_Followers]]-Engagement_Summary[[#This Row],[Unfollows]] -> 1121 | G12: =(Engagement_Summary[[#This Row],[New_Followers]]-Engagement_Summary[[#This Row],[Unfollows]])/Engagement_Summary[[#This Row],[Total_Followers]] -> 0.0087155963 | H12: 7.11 | I12: 12399
A13: 45467 | B13: YouTube | C13: 844 | D13: 144 | E13: 126015 | F13: =Engagement_Summary[[#This Row],[New_Followers]]-Engagement_Summary[[#This Row],[Unfollows]] -> 700 | G13: =(Engagement_Summary[[#This Row],[New_Followers]]-Engagement_Summary[[#This Row],[Unfollows]])/Engagement_Summary[[#This Row],[Total_Followers]] -> 0.0055548943 | H13: 9.65 | I13: 22456
... A201: 45908 | B201: Twitter | C201: 860 | D201: 244 | E201: 348686 | F201: =Engagement_Summary[[#This Row],[New_Followers]]-Engagement_Summary[[#This Row],[Unfollows]] -> 616 | G201: =(Engagement_Summary[[#This Row],[New_Followers]]-Engagement_Summary[[#This Row],[Unfollows]])/Engagement_Summary[[#This Row],[Total_Followers]] -> 0.0017666324 | H201: 5.12 | I201: 11418

Sheet Campaign Metadata
A1: Campaign_Name | B1: Start_Date | C1: End_Date | D1: Objective | E1: Total_Budget | F1: Target_Platforms_1 | G1: Target_Platforms_2 | H1: Primary_Hashtags_1 | I1: Primary_Hashtags_2
A2: SummerBeats | B2: 45458 | C2: 45488 | D2: Brand Awareness | E2: 175000 | F2: Instagram | G2: YouTube | H2: #SpotifyWrapped | I2: #MusicForEveryone
A3: Wrapped2024 | B3: 45627 | C3: 45657 | D3: Engagement | E3: 225000 | F3: Twitter | G3: YouTube | H3: #SpotifyWrapped | I3: #NowPlaying
A4: ChillVibes | B4: 45667 | C4: 45698 | D4: Product Launch | E4: 200000 | F4: Instagram | G4: Twitter | H4: #ChillVibes | I4: #SoundtrackOfLife
A5: IndieWave | B5: 45717 | C5: 45747 | D5: Traffic | E5: 160000 | F5: Facebook | G5: Instagram | H5: #DiscoverWeekly | I5: #IndieWave

Sheet Seprated Hashtag
A1: Post ID | B1: Platform | C1: Date | D1: Content Type | E1: Post Text | F1: Likes | G1: Shares | H1: Comments | I1: Impressions | J1: Engagement Rate | K1: Reach | L1: Clicks | M1: Campaign_Name | N1: Hashtag
A2: SP001 | B2: Instagram | C2: 45781 | D2: Text | E2: Discover fresh beats on Spotify! | F2: 2414 | G2: 245 | H2: 137 | I2: 21181 | J2: 0.1320051 | K2: 45292 | L2: 133 | M2: ChillVibes | N2: #SoundtrackOfLife
A3: SP001 | B3: Instagram | C3: 45781 | D3: Text | E3: Discover fresh beats on Spotify! | F3: 2414 | G3: 245 | H3: 137 | I3: 21181 | J3: 0.1320051 | K3: 45292 | L3: 133 | M3: ChillVibes | N3: #NowPlaying
A4: SP002 | B4: Instagram | C4: 45689 | D4: Text | E4: Explore the latest podcasts now. | F4: 1934 | G4: 210 | H4: 393 | I4: 29129 | J4: 0.087095335 | K4: 73287 | L4: 273 | M4: IndieWave | N4: #DiscoverWeekly
A5: SP003 | B5: Twitter | C5: 45629 | D5: Story | E5: New music just dropped. Hit play! | F5: 3092 | G5: 177 | H5: 81 | I5: 47533 | J5: 0.070477353 | K5: 29220 | L5: 121 | M5: ChillVibes | N5: #MusicForEveryone
A6: SP003 | B6: Twitter | C6: 45629 | D6: Story | E6: New music just dropped. Hit play! | F6: 3092 | G6: 177 | H6: 81 | I6: 47533 | J6: 0.070477353 | K6: 29220 | L6: 121 | M6: ChillVibes | N6: #NowPlaying
A7: SP004 | B7: Instagram | C7: 45629 | D7: Text | E7: Wrapped is here! Relive your top tracks ðŸŽ§ | F7: 3173 | G7: 229 | H7: 197 | I7: 29604 | J7: 0.12157141 | K7: 21809 | L7: 272 | M7: ChillVibes | N7: #SoundtrackOfLife
A8: SP004 | B8: Instagram | C8: 45629 | D8: Text | E8: Wrapped is here! Relive your top tracks ðŸŽ§ | F8: 3173 | G8: 229 | H8: 197 | I8: 29604 | J8: 0.12157141 | K8: 21809 | L8: 272 | M8: ChillVibes | N8: #NowPlaying
A9: SP005 | B9: YouTube | C9: 45388 | D9: Text | E9: Music that moves youâ€”only on Spotify. | F9: 2748 | G9: 145 | H9: 315 | I9: 24401 | J9: 0.13147002 | K9: 61182 | L9: 200 | M9: IndieWave | N9: #DiscoverWeekly
A10: SP005 | B10: YouTube | C10: 45388 | D10: Text | E10: Music that moves youâ€”only on Spotify. | F10: 2748 | G10: 145 | H10: 315 | I10: 24401 | J10: 0.13147002 | K10: 61182 | L10: 200 | M10: IndieWave | N10: #SpotifyWrapped
A11: SP006 | B11: YouTube | C11: 45456 | D11: Text | E11: Whatâ€™s your vibe today? #SpotifyHits | F11: 3882 | G11: 239 | H11: 275 | I11: 58748 | J11: 0.074828079 | K11: 44646 | L11: 149 | M11: IndieWave | N11: #DiscoverWeekly
A12: SP006 | B12: YouTube | C12: 45456 | D12: Text | E12: Whatâ€™s your vibe today? #SpotifyHits | F12: 3882 | G12: 239 | H12: 275 | I12: 58748 | J12: 0.074828079 | K12: 44646 | L12: 149 | M12: IndieWave | N12: #SpotifyWrapped
A13: SP007 | B13: Twitter | C13: 45645 | D13: Story | E13: Get into the groove with our new drop! | F13: 4674 | G13: 409 | H13: 327 | I13: 20756 | J13: 0.26064752 | K13: 63599 | L13: 212 | M13: ChillVibes | N13: #SoundtrackOfLife
... A484: SP300 | B484: Instagram | C484: 45329 | D484: Text | E484: Music that moves youâ€”only on Spotify. | F484: 1883 | G484: 432 | H484: 397 | I484: 28759 | J484: 0.094300914 | K484: 18691 | L484: 270 | M484: ChillVibes | N484: #NowPlaying

Sheet 5.1.1Campaign Effectiveness
A3: 5.1.1 Total & Average Impressions, Likes, Clicks Per Campaign
A4: Row Labels | B4: Sum of Likes | C4: Average of Likes | D4: Sum of Clicks | E4: Average of Clicks | F4: Sum of Impressions | G4: Average of Impressions
A5: ChillVibes | B5: 471034 | C5: 3058.6623 | D5: 28708 | E5: 186.41558 | F5: 6331868 | G5: 41116.026
A6: IndieWave | B6: 274455 | C6: 2919.734 | D6: 18717 | E6: 199.11702 | F6: 4039305 | G6: 42971.33
A7: SummerBeats | B7: 89871 | C7: 3099 | D7: 5557 | E7: 191.62069 | F7: 1233853 | G7: 42546.655
A8: Wrapped2024 | B8: 61815 | C8: 2687.6087 | D8: 4614 | E8: 200.6087 | F8: 865406 | G8: 37626.348

Sheet 5.1.2
A3: 5.1.2 Engagement Uplift During VS Before Campaign
A4: Campaign Name | B4: Start Date | C4: End Date | D4: Campaign Days | E4: Pre_Campaign Start | F4: Pre_Campaign End | G4: Engagement During | H4: Engagement Before | I4: Daily engagement During | J4: Daily engagement Before | K4: Engagement Uplift%
A5: IndieWave | B5: 45717 | C5: 45747 | D5: =(C5-B5)+1 -> 31 | E5: =EDATE(B5,-1) -> 45689 | F5: 45716 | G5: =SUMIFS(Posts!P:P,Posts!O:O,'5.1.2'!A5,Posts!C:C,">="&'5.1.2'!B5,Posts!C:C,"<="&'5.1.2'!C5) -> 27073 | H5: =SUMIFS(Posts!$P:$P,Posts!$O:$O,'5.1.2'!$A5,Posts!$C:$C,">="&E5,Posts!$C:$C,"<="&'5.1.2'!F5) -> 2537 | I5: =G5/D5 -> 873.32258 | J5: =H5/30 -> 84.566667 | K5: =(Table4[[#This Row],[Daily engagement During]]-Table4[[#This Row],[Daily engagement Before]])/Table4[[#This Row],[Daily engagement During]] -> 0.90316675
A6: Wrapped2024 | B6: 45627 | C6: 45657 | D6: =(C6-B6)+1 -> 31 | E6: =EDATE(B6,-1) -> 45597 | F6: 45626 | G6: =SUMIFS(Posts!P:P,Posts!O:O,'5.1.2'!A6,Posts!C:C,">="&'5.1.2'!B6,Posts!C:C,"<="&'5.1.2'!C6) -> 9546 | H6: =SUMIFS(Posts!$P:$P,Posts!$O:$O,'5.1.2'!$A6,Posts!$C:$C,">="&E6,Posts!$C:$C,"<="&'5.1.2'!F6) -> 2424 | I6: =G6/D6 -> 307.93548 | J6: =H6/30 -> 80.8 | K6: =(Table4[[#This Row],[Daily engagement During]]-Table4[[#This Row],[Daily engagement Before]])/Table4[[#This Row],[Daily engagement During]] -> 0.73760737
A7: ChillVibes | B7: 45667 | C7: 45698 | D7: =(C7-B7)+1 -> 32 | E7: =EDATE(B7,-1) -> 45636 | F7: 45666 | G7: =SUMIFS(Posts!P:P,Posts!O:O,'5.1.2'!A7,Posts!C:C,">="&'5.1.2'!B7,Posts!C:C,"<="&'5.1.2'!C7) -> 40373 | H7: =SUMIFS(Posts!$P:$P,Posts!$O:$O,'5.1.2'!$A7,Posts!$C:$C,">="&E7,Posts!$C:$C,"<="&'5.1.2'!F7) -> 54796 | I7: =G7/D7 -> 1261.6562 | J7: =H7/30 -> 1826.5333 | K7: =(Table4[[#This Row],[Daily engagement During]]-Table4[[#This Row],[Daily engagement Before]])/Table4[[#This Row],[Daily engagement During]] -> -0.44772662
A8: SummerBeats | B8: 45458 | C8: 45488 | D8: =(C8-B8)+1 -> 31 | E8: =EDATE(B8,-1) -> 45427 | F8: 45457 | G8: =SUMIFS(Posts!$P:$P,Posts!$O:$O,'5.1.2'!$A8,Posts!$C:$C,">="&'5.1.2'!$B8,Posts!$C:$C,"<="&'5.1.2'!$C8) -> 7338 | H8: =SUMIFS(Posts!$P:$P,Posts!$O:$O,'5.1.2'!$A8,Posts!$C:$C,">="&E8,Posts!$C:$C,"<="&'5.1.2'!F8) -> 12284 | I8: =G8/D8 -> 236.70968 | J8: =H8/30 -> 409.46667 | K8: =(Table4[[#This Row],[Daily engagement During]]-Table4[[#This Row],[Daily engagement Before]])/Table4[[#This Row],[Daily engagement During]] -> -0.72982647

Sheet 5.2.1
A3: 5.2.1 Campaign Roi Engagement VS Ad Spend
A4: Campaign Name | B4: Campaign Ad spend | C4: Total Engagement | D4: ROI
A5: ChillVibes | B5: =SUMIFS('Engagement Summary'!I:I,'Engagement Summary'!B:B,"Twitter",'Engagement Summary'!A:A,">="&'Campaign Metadata'!B4,'Engagement Summary'!A:A,"<="&'Campaign Metadata'!C4)+SUMIFS('Engagement Summary'!I:I,'Engagement Summary'!B:B,"YouTube",'Engagement Summary'!A:A,">="&'Campaign Metadata'!B4,'Engagement Summary'!A:A,"<="&'Campaign Metadata'!C4) -> 133793 | C5: =SUMIFS(Posts[Total Enagagement],Posts[Campaign_Name],A5) -> 551989 | D5: =B5/C5 -> 0.24238345
A6: IndieWave | B6: =SUMIFS('Engagement Summary'!I:I,'Engagement Summary'!B:B,"Twitter",'Engagement Summary'!A:A,">="&'Campaign Metadata'!B5,'Engagement Summary'!A:A,"<="&'Campaign Metadata'!C5)+SUMIFS('Engagement Summary'!I:I,'Engagement Summary'!B:B,"YouTube",'Engagement Summary'!A:A,">="&'Campaign Metadata'!B5,'Engagement Summary'!A:A,"<="&'Campaign Metadata'!C5) -> 172589 | C6: =SUMIFS(Posts[Total Enagagement],Posts[Campaign_Name],A6) -> 324406 | D6: =B6/C6 -> 0.53201544
A7: SummerBeats | B7: =SUMIFS('Engagement Summary'!I:I,'Engagement Summary'!B:B,"Twitter",'Engagement Summary'!A:A,">="&'Campaign Metadata'!B2,'Engagement Summary'!A:A,"<="&'Campaign Metadata'!C2)+SUMIFS('Engagement Summary'!I:I,'Engagement Summary'!B:B,"YouTube",'Engagement Summary'!A:A,">="&'Campaign Metadata'!B2,'Engagement Summary'!A:A,"<="&'Campaign Metadata'!C2) -> 174329 | C7: =SUMIFS(Posts[Total Enagagement],Posts[Campaign_Name],"SummerBeats") -> 105783 | D7: =B7/C7 -> 1.6479869
A8: Wrapped2024 | B8: =SUMIFS('Engagement Summary'!I:I,'Engagement Summary'!B:B,"Twitter",'Engagement Summary'!A:A,">="&'Campaign Metadata'!B3,'Engagement Summary'!A:A,"<="&'Campaign Metadata'!C3)+SUMIFS('Engagement Summary'!I:I,'Engagement Summary'!B:B,"YouTube",'Engagement Summary'!A:A,">="&'Campaign Metadata'!B3,'Engagement Summary'!A:A,"<="&'Campaign Metadata'!C3) -> 143172 | C8: =SUMIFS(Posts[Total Enagagement],Posts[Campaign_Name],A8) -> 75464 | D8: =B8/C8 -> 1.8972225

Sheet 5.2.2
A4: 5.2.2 Campaign With Strongest Follower
A5: Campaign Name | B5: Start Date | C5: End Date | D5: Net Followers
A6: SummerBeats | B6: 45458 | C6: 45488 | D6: =SUMIFS('Engagement Summary'!F:F,'Engagement Summary'!B:B,"Instagram",'Engagement Summary'!A:A,">="&'5.2.2'!B6,'Engagement Summary'!A:A,"<="&'5.2.2'!C6)+SUMIFS('Engagement Summary'!F:F,'Engagement Summary'!B:B,"YouTube",'Engagement Summary'!A:A,">="&'5.2.2'!B6,'Engagement Summary'!A:A,"<="&'5.2.2'!C6) -> 8090
A7: Wrapped2024 | B7: 45627 | C7: 45657 | D7: =SUMIFS('Engagement Summary'!F:F,'Engagement Summary'!B:B,"Twitter",'Engagement Summary'!A:A,">="&'5.2.2'!B7,'Engagement Summary'!A:A,"<="&'5.2.2'!C7)+SUMIFS('Engagement Summary'!F:F,'Engagement Summary'!B:B,"YouTube",'Engagement Summary'!A:A,">="&'5.2.2'!B7,'Engagement Summary'!A:A,"<="&'5.2.2'!C7) -> 7845
A8: ChillVibes | B8: 45667 | C8: 45698 | D8: =SUMIFS('Engagement Summary'!F:F,'Engagement Summary'!B:B,"Instagram",'Engagement Summary'!A:A,">="&'5.2.2'!B8,'Engagement Summary'!A:A,"<="&'5.2.2'!C8)+SUMIFS('Engagement Summary'!F:F,'Engagement Summary'!B:B,"Twitter",'Engagement Summary'!A:A,">="&'5.2.2'!B8,'Engagement Summary'!A:A,"<="&'5.2.2'!C8) -> 7300
A9: IndieWave | B9: 45717 | C9: 45747 | D9: =SUMIFS('Engagement Summary'!F:F,'Engagement Summary'!B:B,"Instagram",'Engagement Summary'!A:A,">="&'5.2.2'!B9,'Engagement Summary'!A:A,"<="&'5.2.2'!C9)+SUMIFS('Engagement Summary'!F:F,'Engagement Summary'!B:B,"Facebook",'Engagement Summary'!A:A,">="&'5.2.2'!B9,'Engagement Summary'!A:A,"<="&'5.2.2'!C9) -> 3389
